# Try and Catch with Async/Await

The **try...catch** statement in JavaScript is used to handle exceptions and errors gracefully. It is particularly useful with `async/await` functions for managing errors in asynchronous code.

---

## Basic Syntax

The `try` block contains the code to execute, while the `catch` block handles errors if they occur.

**Example**:
```js
try {
  const x = 2;
  x = 3; // Error: Assignment to constant variable
} catch (err) {
  console.log(err.message); // Output: Assignment to constant variable
}
```

---

## Using Try and Catch with Async/Await

When working with asynchronous code, `try...catch` is used to handle errors that may occur during the execution of `await` operations.

**Example**:
```js 
async function fetchData() {
  try {
    const response = await fetch('https://api.example.com/data');
    const data = await response.json();
    console.log(data);
  } catch (err) {
    console.error('Error fetching data:', err.message);
  }
}

fetchData();
```

---

## Handling Multiple Errors

You can use multiple `try...catch` blocks for more granular error handling.

**Example**:
```js
async function handleErrors() {
  try {
    const user = await fetch('https://api.example.com/user').then((res) => res.json());
    console.log(user);
  } catch (err) {
    console.error('Error fetching user:', err.message);
  }

  try {
    const posts = await fetch('https://api.example.com/posts').then((res) => res.json());
    console.log(posts);
  } catch (err) {
    console.error('Error fetching posts:', err.message);
  }
}

handleErrors();
```

---

## Combining Try and Catch with Finally

The `finally` block executes code after the `try` and `catch` blocks, regardless of whether an error occurred.

**Example**:
```js
async function fetchDataWithFinally() {
  try {
    const response = await fetch('https://api.example.com/data');
    const data = await response.json();
    console.log(data);
  } catch (err) {
    console.error('Error:', err.message);
  } finally {
    console.log('Fetch operation complete.');
  }
}

fetchDataWithFinally();
```

---

## Important Notes for Interviews

1. **Why Use Try and Catch with Async/Await?**
   - Handles errors in `await` operations in a synchronous-like manner.
   - Avoids the complexity of chaining `.catch()` in Promises.

2. **Common Mistakes**:
   - Forgetting to wrap `await` operations in `try...catch`, resulting in unhandled rejections.
   - Using `try...catch` for non-critical errors; sometimes a `.catch()` at the end of the Promise chain is sufficient.

3. **Best Practices**:
   - Use `try...catch` sparingly to avoid overly nested blocks.
   - Combine with `finally` for cleanup actions, such as closing resources or updating UI states.

4. **Tech Questions**:
   - How do you handle errors in `async/await` functions?
   - What is the purpose of the `finally` block, and how does it work?
   - What are the advantages of `try...catch` over `.catch()` for Promises?

